<?xml version="1.0"?>
<robot name="bottle_skeleton">
    <link name="world" />
    <link name="bottle_free">
        <inertial>
            <mass value="1.0" />
            <origin xyz="0 0 0" rpy="0 0 0" />
            <inertia ixx="1.0" ixy="0" ixz="0" iyy="1.0" iyz="0" izz="1.0" />
        </inertial>
        <visual>
            <origin xyz="0 0 0" rpy="0 0 0" />
            <geometry>

                <mesh filename="meshes/ur5/visual/wine_bottle.stl" scale="0.001 0.001 0.001"/>
            </geometry>     
            <material name="LightGrey">
                <color rgba="0.7 0.7 0.7 1.0"/>
            </material>   
        </visual>
        <collision group="default">
            <origin xyz="0 0 0" rpy="0 0 0" />
            <geometry>
                <mesh filename="meshes/ur5/visual/wine_bottle.stl" scale="0.001 0.001 0.001"/>
            </geometry>          
        </collision>
    </link>
    <joint name="bot" type="floating">
        <origin xyz="0.4 0 0.4" rpy="-1.57075 0 0" />
        <parent link="world" />
        <child link="bottle_free" />
    </joint>
</robot>
