<?xml version="1.0"?>
<robot name="bottle_skeleton">
    <link name="world" />
    <link name="bottle_free">
        <inertial>
            <mass value="0.0001" />
            <origin xyz="0 0 0" rpy="0 0 0" />
            <inertia ixx="1.0" ixy="0" ixz="0" iyy="1.0" iyz="0" izz="1.0" />
        </inertial>
        <visual>
            <origin xyz="0 0 0" rpy="0 0 0" />
            <geometry>
                <mesh filename="box.obj" scale="0.02 0.08 0.02" />
            </geometry>     

            <material name="LightGrey">
                <color rgba="0.7 0.7 0.7 1.0"/>
            </material>   
        </visual>
        <collision group="default">
            <origin xyz="0 0 0" rpy="0 0 0" />
            <geometry>
                <mesh filename="box.obj" scale="0.02 0.08 0.02" />
            </geometry>
            <!-- <surface>
            <friction>
                <ode>
                <mu>100</mu>
                <mu2>50</mu2>
                </ode>
            </friction>
            </surface> -->
        </collision>
    </link>
    <joint name="bot" type="floating">
        <origin xyz="-0.5 0.07 0.035" rpy="0 0 0" />
        <!-- -0.50 0.1 0.035 -->
        <parent link="world" />
        <child link="bottle_free" />
    </joint>
</robot>
