<?xml version="1.0"?>
<robot name="ur5">

  <link name="world" />

  <joint name="base_link_fix" type="fixed">
      <origin xyz="0 0 0" rpy="1.57079633 -1.57079633  3.14" />
      <parent link="world" />
      <child link="base_link" />
  </joint>

  <link name="base_link">
    <visual>
      <geometry>
        <mesh filename="meshes/ur5/visual/base.stl"/>
      </geometry>
      <material name="LightGrey">
        <color rgba="0.7 0.7 0.7 1.0"/>
      </material>
    </visual>
    <collision>
      <geometry>
        <mesh filename="meshes/ur5/visual/base.stl"/>
      </geometry>
    </collision>
    <inertial>
      <mass value="4.0"/>
      <origin rpy="0 0 0" xyz="0.0 0.0 0.0"/>
      <inertia ixx="0.00443333156" ixy="0.0" ixz="0.0" iyy="0.00443333156" iyz="0.0" izz="0.0072"/>
    </inertial>
  </link>

  <joint name="shoulder_pan_joint" type="revolute">
    <parent link="base_link"/>
    <child link="shoulder_link"/>
    <origin rpy="0.0 0.0 0.0" xyz="0.0 0.0 0.089159"/>
    <axis xyz="0 0 1"/>
    <limit effort="150.0" lower="-3.14159265" upper="3.14159265" velocity="3.15"/>
    <dynamics damping="0.0" friction="0.0"/>
  </joint>

  <link name="shoulder_link">
    <visual>
      <geometry>
        <mesh filename="meshes/ur5/visual/shoulder.stl"/>
      </geometry>
      <material name="LightGrey">
        <color rgba="0.7 0.7 0.7 1.0"/>
      </material>
    </visual>
    <collision>
      <geometry>
        <mesh filename="meshes/ur5/visual/shoulder.stl"/>
      </geometry>
    </collision>
    <inertial>
      <mass value="3.7"/>
      <origin rpy="0 0 0" xyz="0.0 0.0 0.0"/>
      <inertia ixx="0.010267495893" ixy="0.0" ixz="0.0" iyy="0.010267495893" iyz="0.0" izz="0.00666"/>
    </inertial>
  </link>

  <joint name="shoulder_lift_joint" type="revolute">
    <parent link="shoulder_link"/>
    <child link="upper_arm_link"/>
    <origin rpy="0.0 1.570796325 0.0" xyz="0.0 0.13585 0.0"/>
    <axis xyz="0 1 0"/>
    <limit effort="150.0" lower="-3.14159265" upper="-0.9" velocity="3.15"/>
    <!-- <limit effort="150.0" lower="-3.14159265" upper="-0.8" velocity="3.15"/> -->
    <dynamics damping="0.0" friction="0.0"/>
  </joint>

  <link name="upper_arm_link">
    <visual>
      <geometry>
        <mesh filename="meshes/ur5/visual/upperarm.stl"/>
      </geometry>
      <material name="LightGrey">
        <color rgba="0.7 0.7 0.7 1.0"/>
      </material>
    </visual>
    <collision>
      <geometry>
        <mesh filename="meshes/ur5/visual/upperarm.stl"/>
      </geometry>
    </collision>
    <inertial>
      <mass value="8.393"/>
      <origin rpy="0 0 0" xyz="0.0 0.0 0.28"/>
      <inertia ixx="0.22689067591" ixy="0.0" ixz="0.0" iyy="0.22689067591" iyz="0.0" izz="0.0151074"/>
    </inertial>
  </link>

  <joint name="elbow_joint" type="revolute">
    <parent link="upper_arm_link"/>
    <child link="forearm_link"/>
    <origin rpy="0.0 0.0 0.0" xyz="0.0 -0.1197 0.425"/>
    <axis xyz="0 1 0"/>
    <limit effort="150.0" lower="-3.14159265" upper="3.14159265" velocity="3.15"/>
    <dynamics damping="0.0" friction="0.0"/>
  </joint>

  <link name="forearm_link">
    <visual>
      <geometry>
        <mesh filename="meshes/ur5/visual/forearm.stl"/>
      </geometry>
      <material name="LightGrey">
        <color rgba="0.7 0.7 0.7 1.0"/>
      </material>
    </visual>
    <collision>
      <geometry>
        <mesh filename="meshes/ur5/visual/forearm.stl"/>
      </geometry>
    </collision>
    <inertial>
      <mass value="2.275"/>
      <origin rpy="0 0 0" xyz="0.0 0.0 0.25"/>
      <inertia ixx="0.049443313556" ixy="0.0" ixz="0.0" iyy="0.049443313556" iyz="0.0" izz="0.004095"/>
    </inertial>
  </link>

  <joint name="wrist_1_joint" type="revolute">
    <parent link="forearm_link"/>
    <child link="wrist_1_link"/>
    <origin rpy="0.0 1.570796325 0.0" xyz="0.0 0.0 0.39225"/>
    <axis xyz="0 1 0"/>
    <limit effort="28.0" lower="-3.14159265" upper="3.14159265" velocity="3.2"/>
    <dynamics damping="0.0" friction="0.0"/>
  </joint>

  <link name="wrist_1_link">
    <visual>
      <geometry>
        <mesh filename="meshes/ur5/visual/wrist1.stl"/>
      </geometry>
      <material name="LightGrey">
        <color rgba="0.7 0.7 0.7 1.0"/>
      </material>
    </visual>
    <collision>
      <geometry>
        <mesh filename="meshes/ur5/visual/wrist1.stl"/>
      </geometry>
    </collision>
    <inertial>
      <mass value="1.219"/>
      <origin rpy="0 0 0" xyz="0.0 0.0 0.0"/>
      <inertia ixx="0.111172755531" ixy="0.0" ixz="0.0" iyy="0.111172755531" iyz="0.0" izz="0.21942"/>
    </inertial>
  </link>

  <joint name="wrist_2_joint" type="revolute">
    <parent link="wrist_1_link"/>
    <child link="wrist_2_link"/>
    <origin rpy="0.0 0.0 0.0" xyz="0.0 0.093 0.0"/>
    <axis xyz="0 0 1"/>
    <limit effort="28.0" lower="-3.14159265" upper="3.14159265" velocity="3.2"/>
    <dynamics damping="0.0" friction="0.0"/>
  </joint>

  <link name="wrist_2_link">
    <visual>
      <geometry>
        <mesh filename="meshes/ur5/visual/wrist2.stl"/>
      </geometry>
      <material name="LightGrey">
        <color rgba="0.7 0.7 0.7 1.0"/>
      </material>
    </visual>
    <collision>
      <geometry>
        <mesh filename="meshes/ur5/visual/wrist2.stl"/>
      </geometry>
    </collision>
    <inertial>
      <mass value="1.219"/>
      <origin rpy="0 0 0" xyz="0.0 0.0 0.0"/>
      <inertia ixx="0.111172755531" ixy="0.0" ixz="0.0" iyy="0.111172755531" iyz="0.0" izz="0.21942"/>
    </inertial>
  </link>

  <joint name="wrist_3_joint" type="revolute">
    <parent link="wrist_2_link"/>
    <child link="wrist_3_link"/>
    <origin rpy="0.0 0.0 0.0" xyz="0.0 0.0 0.09465"/>
    <axis xyz="0 1 0"/>
    <limit effort="28.0" lower="-3.14159265" upper="3.14159265" velocity="3.2"/>
    <dynamics damping="0.0" friction="0.0"/>
  </joint>

  <link name="wrist_3_link">
    <visual>
      <geometry>
        <mesh filename="meshes/ur5/visual/wrist3.stl"/>
      </geometry>
      <material name="LightGrey">
        <color rgba="0.7 0.7 0.7 1.0"/>
      </material>
    </visual>
    <collision>
      <geometry>
        <mesh filename="meshes/ur5/visual/wrist3.stl"/>
      </geometry>
    </collision>
    <inertial>
      <mass value="0.1879"/>
      <origin rpy="0 0 0" xyz="0.0 0.0 0.0"/>
      <inertia ixx="0.0171364731454" ixy="0.0" ixz="0.0" iyy="0.0171364731454" iyz="0.0" izz="0.033822"/>
    </inertial>
  </link>

  <joint name="ee_fixed_joint" type="fixed">
    <parent link="wrist_3_link"/>
    <child link="ee_link"/>
    <origin rpy="0.0 0.0 1.570796325" xyz="0.0 0.0823 0.0"/>
  </joint>

  <link name="ee_link">
    <collision>
      <geometry>
        <box size="0.01 0.01 0.01"/>
      </geometry>
      <origin rpy="0 0 0" xyz="-0.01 0 0"/>
    </collision>
    <visual>
      <geometry>
        <box size="0.01 0.01 0.01"/>
      </geometry>
      <material name="LightGrey">
        <color rgba="0.7 0.7 0.7 1.0"/>
      </material>
    </visual>
  </link>

  <joint name="ee_link_to_robotiq_base_link" type="fixed">
    <parent link="ee_link"/>
    <child link="robotiq_base_link"/>
    <origin rpy="1.57079633 0.0 1.57079633" xyz="0 0 0"/>
  </joint>

  <link name="robotiq_base_link">
    <visual>
      <geometry>
        <mesh filename="meshes/ur5/visual/robotiq_85_base_link_coarse.stl"/>
      </geometry>
      <material name="LightGrey">
        <color rgba="0.7 0.7 0.7 1.0"/>
      </material>
    </visual>
    <collision>
      <geometry>
        <mesh filename="meshes/ur5/visual/robotiq_85_base_link_coarse.stl"/>
      </geometry>
    </collision>
    <inertial>
      <mass value="0.30915"/>
      <origin xyz="0.00021987 -2.3546e-10 0.030163" rpy="2.04599906e-02 -6.72138114e-07  1.57082885e+00"/>
      <inertia ixx="0.00030737" ixy="0.0" ixz="0.0" iyy="0.000289758" iyz="0.0" izz="0.000199102"/>
    </inertial>
  </link>

  <joint name="base_to_lik" type="revolute">
    <parent link="robotiq_base_link"/>
    <child link="left_inner_knuckle"/>
    <origin xyz="0.0127 0 0.0693075" rpy="0 0 0"/>
    <axis xyz="0 1 0"/>
    <limit lower="-1" upper="1" effort="20" velocity="3.2"/>
    <dynamics damping="0.01" friction="0.004"/>
    <!-- <mimic joint="base_to_rik" multiplier="-1" offset="0"/> -->
  </joint>


  <link name="left_inner_knuckle">
    <!-- <contact>
      <friction_anchor/>
      <stiffness value="30000.0"/>
      <damping value="1000.0"/>
      <spinning_friction value="0.1"/>
      <lateral_friction value="1.0"/>
    </contact> -->
    <visual>
      <geometry>
        <mesh filename="meshes/ur5/visual/inner_knuckle_coarse.stl"/>
      </geometry>
      <material name="LightGrey">
        <color rgba="0.7 0.7 0.7 1.0"/>
      </material>
    </visual>
    <inertial>
      <mass value="0.0110931"/>
      <origin xyz="0.0170975 -3.93809e-10 0.0224918" rpy="0.0 -0.64997493  0.0"/>
      <inertia ixx="5.59353e-06" ixy="0.0" ixz="0.0" iyy="3.96549e-06" iyz="0.0" izz="1.88108e-06"/>
    </inertial>
    <collision>
      <geometry>
        <mesh filename="meshes/ur5/visual/inner_knuckle_coarse.stl"/>
      </geometry>
    </collision>
  </link>

  <joint name="base_to_rik" type="revolute">
    <parent link="robotiq_base_link"/>
    <child link="right_inner_knuckle"/>
    <origin xyz="-0.0127 0 0.0693075" rpy="0.0 0.0 3.14159265"/>
    <axis xyz="0 1 0"/>
    <limit lower="-1" upper="1" effort="20" velocity="3.2"/>
    <dynamics damping="0.01" friction="0.004"/>
  </joint>
  
  <!-- <equality>
    <joint name="fingers" joint1="base_to_rik" joint2="base_to_lik" polycoef="0 1 0 0 0"/>
  </equality> -->

  <link name="right_inner_knuckle">
    <!-- <contact>
      <friction_anchor/>
      <stiffness value="30000.0"/>
      <damping value="1000.0"/>
      <spinning_friction value="0.1"/>
      <lateral_friction value="1.0"/>
    </contact> -->
    <visual>
      <geometry>
        <mesh filename="meshes/ur5/visual/inner_knuckle_coarse.stl"/>
      </geometry>
      <material name="LightGrey">
        <color rgba="0.7 0.7 0.7 1.0"/>
      </material>
    </visual>

    <inertial>
      <mass value="0.0110931"/>
      <origin xyz="0.0168606 3.93808e-10 0.02267" rpy="0.0 -0.64997493  0.0"/>
      <inertia ixx="5.59353e-06" ixy="0.0" ixz="0.0" iyy="3.96549e-06" iyz="0.0" izz="1.88108e-06"/>
    </inertial>
    <collision>
      <geometry>
        <mesh filename="meshes/ur5/visual/inner_knuckle_coarse.stl"/>
      </geometry>
    </collision>
  </link>

  <joint name="lik_to_lif" type="fixed">
    <parent link="left_inner_knuckle"/>
    <child link="left_inner_finger"/>
    <origin xyz="0.0345853 0 0.045497" rpy="0 0 0"/>
  </joint>

  <link name="left_inner_finger">
    <visual>
      <geometry>
        <mesh filename="meshes/ur5/visual/inner_finger_coarse.stl"/>
      </geometry>
      <material name="LightGrey">
        <color rgba="0.7 0.7 0.7 1.0"/>
      </material>
    </visual>
    <inertial>
      <mass value="0.00724255"/>
      <origin xyz="0.00602756 0 0.00669926" rpy="0.30191756 0.0 1.57079633"/>
      <inertia ixx="1.70064e-06" ixy="0.0" ixz="0.0" iyy="1.58577e-06" iyz="0.0" izz="3.69621e-07"/>
    </inertial>
    <collision>
      <geometry>
        <mesh filename="meshes/ur5/visual/inner_finger_coarse.stl"/>
      </geometry>
    </collision>
  </link>



  <joint name="rik_to_rif" type="fixed">
    <parent link="right_inner_knuckle"/>
    <child link="right_inner_finger"/>
    <origin xyz="0.0345853 0 0.045497" rpy="0 0 0"/>
  </joint>

  <link name="right_inner_finger">
    <visual>
      <geometry>
        <mesh filename="meshes/ur5/visual/inner_finger_coarse.stl"/>
      </geometry>
      <material name="LightGrey">
        <color rgba="0.7 0.7 0.7 1.0"/>
      </material>
    </visual>
    <inertial>
      <mass value="0.00724255"/>
      <origin xyz="0.00602756 0 0.00669926" rpy="0.30191756 0.0 1.57079633"/>
      <inertia ixx="1.70064e-06" ixy="0.0" ixz="0.0" iyy="1.58577e-06" iyz="0.0" izz="3.69621e-07"/>
    </inertial>
    <collision>
      <geometry>
        <mesh filename="meshes/ur5/visual/inner_finger_coarse.stl"/>
      </geometry>
    </collision>
  </link>

  <!-- 
  <transmission name="shoulder_pan_trans">
    <type>transmission_interface/SimpleTransmission</type>
    <joint name="shoulder_pan_joint">
      <hardwareInterface>PositionJointInterface</hardwareInterface>
    </joint>
    <actuator name="shoulder_pan_motor">
      <mechanicalReduction>1</mechanicalReduction>
    </actuator>
  </transmission>
  <transmission name="shoulder_lift_trans">
    <type>transmission_interface/SimpleTransmission</type>
    <joint name="shoulder_lift_joint">
      <hardwareInterface>PositionJointInterface</hardwareInterface>
    </joint>
    <actuator name="shoulder_lift_motor">
      <mechanicalReduction>1</mechanicalReduction>
    </actuator>
  </transmission>
  <transmission name="elbow_trans">
    <type>transmission_interface/SimpleTransmission</type>
    <joint name="elbow_joint">
      <hardwareInterface>PositionJointInterface</hardwareInterface>
    </joint>
    <actuator name="elbow_motor">
      <mechanicalReduction>1</mechanicalReduction>
    </actuator>
  </transmission>
  <transmission name="wrist_1_trans">
    <type>transmission_interface/SimpleTransmission</type>
    <joint name="wrist_1_joint">
      <hardwareInterface>PositionJointInterface</hardwareInterface>
    </joint>
    <actuator name="wrist_1_motor">
      <mechanicalReduction>1</mechanicalReduction>
    </actuator>
  </transmission>
  <transmission name="wrist_2_trans">
    <type>transmission_interface/SimpleTransmission</type>
    <joint name="wrist_2_joint">
      <hardwareInterface>PositionJointInterface</hardwareInterface>
    </joint>
    <actuator name="wrist_2_motor">
      <mechanicalReduction>1</mechanicalReduction>
    </actuator>
  </transmission>
  <transmission name="wrist_3_trans">
    <type>transmission_interface/SimpleTransmission</type>
    <joint name="wrist_3_joint">
      <hardwareInterface>PositionJointInterface</hardwareInterface>
    </joint>
    <actuator name="wrist_3_motor">
      <mechanicalReduction>1</mechanicalReduction>
    </actuator>
  </transmission> -->
</robot>
